Workbook

Sheet Uso de estimador
A1: Estimador de HC en base a S0
A2: Elaborado por: Javier Soto
A3: Fecha de creación: 20.08.2024
A4: Versión del documento : V01
A5: La estimación está orientada a consultoría funcional. No incluye estimación de asignación de gerente de proyecto, gerente de consultoría, arquitecto, líder ABAP, roles y perfiles. También se basa en que los consultores tienen un nivel de experiencia adecuado( > 8 años aprox.). Asímismo, se debe estimar por separado la fase deploy en base a otras variables propias del cliente. Igualmente con la fase RUN en base al acuerdo comercial de soporte que se requiera.
A6: Tipos de procesos: La estimación se basa en las diferentes actividades que se realizan en las fase del proyecto dependiedo del tipo de proceso. Tenemos definido los tipos de proceso:
A7: Estructura organizativa: Explicación de estructura organizativa. Definición de información necesaria para la EO(Anexo) Desarrollo de BPD. Configuración.
A8: Datos maestros: Explicación del dato maestros. Desarrollo de BPD. Definición de campos a configurar en dato maestros(Anexos) Inventariar estructura de carga masiva Explorar proceso de carga masiva en Migration Cockpits Soporte a los procesos de carga para pruebas. Soporte a los procesos de carga para PRD.
A9: Proceso: Explicación del proceso. Explicación del diagrama de flujo. Preparación de datos para taller de demostración. Taller de demostración en sistema. Desarrollo de BPD. Definiciones de configuraciones en Anexos. Integración con otros frentes. Revisión de Roles Definición de escenarios de negocio para pruebas. Configuración. Pruebas internas de consultoría. Documentación de consultoría. Pruebas unitarias. Pruebas integrales. CutOver para proceso. Soporte de incidencias.
A10: Reportes: Taller de demostración de reportes. Integración con otros frentes. Revisión de Roles. Creación de variantes. Navegación en SAPGUI / Fiori
A11: Grado de adopción:
A12: Asimismo, se debe indicar el grado de adopción de cada proceso para mejorar la estimación en base al QUAD-A
... A22: 04 Muy alta: Existen muchos registros, muchas variantes y está asociado a desarrollo.

Sheet Atributos
A1: SEIDOR SprintZero V1.0 | P1: Tipo | Q1: Descripción | R1: T. Descubrimiento | S1: T. Preparación Inicial | T1: T. Exploración | U1: T. Realización | V1: T. Despliegue | W1: T. Soporte
P2: DM | Q2: Explicación del dato maestros. Desarrollo de BPD. Definición de campos a configurar en dato maestros(Anexos) Inventariar estructura de carga masiva Explorar proceso de carga masiva en Migration Cockpits Soporte a los procesos de carga para pruebas. Soporte a los procesos de carga para PRD. | R2: 1 | S2: 1 | T2: 8 | U2: 8 | V2: 8 | W2: 0
P3: EO | Q3: Explicación de estructura organizativa. Definición de información necesaria para la EO(Anexo) Desarrollo de BPD. Configuración. | R3: 1 | S3: 1 | T3: 4 | U3: 4 | V3: 0 | W3: 0
A4: Revisado por: Javier Soto Castillo | I4: Line of Business | J4: Responsable | L4: Módulos | M4: RICEF | N4: Fase | P4: PR | Q4: Explicación del proceso. Explicación del diagrama de flujo. Preparación de datos para taller de demostración. Taller de demostración en sistema. Desarrollo de BPD. Definiciones de configuraciones en Anexos. Integración con otros frentes. Revisión de Roles Definición de escenarios de negocio para pruebas. Configuración. Pruebas internas de consultoría. Documentación de consultoría. Pruebas unitarias. Pruebas integrales. CutOver para proceso. Soporte de incidencias. | R4: 1 | S4: 2 | T4: =8+8 -> 16 | U4: =16+8+8 -> 32 | V4: 8 | W4: 8
I5: Manufactura | J5: Javier Soto | L5: PP | M5: Report | N5: Proyecto | P5: RE | Q5: Taller de demostración de reportes. Integración con otros frentes. Revisión de Roles. Creación de variantes. Navegación en SAPGUI / Fiori | R5: 1 | S5: 2 | T5: 4 | U5: =8+8 -> 16 | V5: 0 | W5: 8
A6: Listado de procesos: Contiene todos los procesos configurados. | I6: Gestión de activos | J6: Santiago Sánchez | L6: QM | M6: Interface | N6: Soporte
A7: Listado de RICEF: Contiene todos los RICEF creados. | I7: Finanzas | J7: Yvan Montero | L7: PM | M7: Conversion
I8: Ventas | L8: FI | M8: Enhacenment
I9: Abastecimiento y compras | J9: Luis | L9: CO | M9: Forms
I10: Cadena de suministro | L10: MM | M10: WorkFlows
L11: EWM
A12: Estado | L12: WM
A13: 00 Nuevo | L13: RE
A14: 01 Documentado | L14: PS
A15: 02 Configurado | L15: SD
A16: 03 Probado | L16: HCM
A17: 04 Terminado
A18: 99 Obsoleto
A20: MAXIMO | B20: 1.5 | G20: MINIMO
A21: Complejidad | B21: Factor | G21: Complejidad | H21: Factor
A22: 01 Baja | B22: =+H22*$B$20 -> 1.5 | G22: 01 Baja | H22: 1
A23: 02 Media | B23: =+H23*$B$20 -> 2.25 | G23: 02 Media | H23: 1.5
A24: 03 Alta | B24: =+H24*$B$20 -> 3 | G24: 03 Alta | H24: 2
A25: 04 Muy Alta | B25: =+H25*$B$20 -> 4.5 | G25: 04 Muy Alta | H25: 3
A27: QUAD-A
A28: 01 Adoptar | B28: 1 | E28: 1
A29: 02 Ajustar | B29: 1.5 | E29: 1.5 | I29: =1.5*1.5 -> 2.25
A30: 03 Agregar | B30: 2.5 | E30: 2.5 | I30: =3*1.5 -> 4.5
A31: 04 Abstener | B31: 0 | E31: 0
A33: #Registros
A34: 01 < 0 : 100 > | B34: 2
A35: 02 <100 : 1K > | B35: 3
A36: 03 <1K : 10K > | B36: 4
A37: 04 <10K : 100K > | B37: 6
A38: #Usuarios
A39: 01 <1 : 10 > | B39: 2
A40: 02 <10 : 25 > | B40: 3
A41: 03 <25 : 60 > | B41: 4
A42: 04 <60 : 100> | B42: 5
A43: 05 <100 : 200> | B43: 6
...

Sheet S0
A1: Línea de negocio | B1: Área de negocio | C1: Proceso de negocio | D1: SAP S/4HANA BP | E1: Actividades | F1: Descripción | G1: Variantes | H1: Exclusiones | I1: Mód. | J1: BC_SET_S0 | K1: BC_SET_S0 - Prerequisito | L1: Observaciones | M1: Fase | N1: Anexo BPD | O1: Estructuras de carga masiva | P1: Estado | Q1: TA | R1: Complejidad | S1: TP | T1: Discovery | U1: Prepare | V1: Explore | W1: Realize | X1: Deploy | Y1: Run
A2: Finanzas | B2: EO | C2: CO-00_Estructura organizativa(CO_EO1) | E2: Sociedad CO. Sociedad PA. Jerarquía de Centros de Beneficio Jerarquía de Centros de Costos | F2: En la estructura SAP representa la vista jurídica u organizativa de una empresa como los niveles de la organización. La misma que, corresponde a un requisito esencial tanto para los datos maestros; como para definir, los procesos esenciales. A través de los objetos de costo en dicha estructura; posteriormente, se realizaran las contabilizaciones en las cuentas de ingresos y gastos. | H2: * No se puede cambiar la moneda CO ni PA luego de tener movimientos | I2: CO | J2: YS0_S4HANA_EO_001 YS0_S4HANA_EO_C001 | M2: 1 | P2: 04 Terminado | R2: 1 | S2: EO | T2: =+VLOOKUP(S2,Atributos!$P$2:$W$5,3)*R2 -> 1 | U2: =+VLOOKUP(S2,Atributos!$P$2:$W$5,4)*R2 -> 1 | V2: =+VLOOKUP(S2,Atributos!$P$2:$W$5,5)*R2 -> 4 | W2: =+VLOOKUP(S2,Atributos!$P$2:$W$5,6)*R2 -> 4 | X2: =+VLOOKUP(S2,Atributos!$P$2:$W$5,7)*R2 -> 0 | Y2: =+VLOOKUP(S2,Atributos!$P$2:$W$5,8)*R2 -> 0
A3: Finanzas | B3: Gestión de datos maestros | C3: CO-01_Administración de datos maestros de Controlling(CO_M010) | D3: J58-00_J58-02 | E3: Gestión de Centros de Beneficio. Gestión de Centros de Costos. Gestión de clases de costo. Gestión de valores estadísticos. Gestión de órdenes internas. | F3: Corresponden a los datos que contienen información relevante para los procesos de la empresa y se encuentran almacenados de forma centralizada, para evitar redundancias y son empleadas por las diversas aplicaciones. En la contabilidad de costos tenemos: - Centro de beneficio: Es una unidad organizativa de finanzas que refleja una estructura de la empresa orientada hacia la gestión. Se pueden analizar los resultados operativos con la vinculación a las cuentas de resultado. - Centro de Costos: Es una unidad organizativa de controlling que representa una ubicación delimitada donde se generan los costes. - Gestión de clases de costo: Este maestro comprenden a las cuentas de resultado que tienen injerencia en la contabilidad de costos interna y que se requieren, para realizar los procesos en controlling. - Los valores estadísticos representan los drivers o inductores para distribuir los gastos. - Órdenes internas: Son colectores de costos que permiten acumular costos de eventos específicos, campañas, inversiones, etc. | G3: * Crear varios tipos de Ordenes Internas | H3: * La data maestra luego de tener movimiento no puede ser eliminada | I3: CO | J3: YS0_S4HANA_EO_001 YS0_S4HANA_EO_C001 | M3: 1 | N3: ANEXO_CO01 - Área Funcional ANEXO_CO02 - Segmento | P3: 04 Terminado | R3: 1 | S3: DM | T3: =+VLOOKUP(S3,Atributos!$P$2:$W$5,3)*R3 -> 1 | U3: =+VLOOKUP(S3,Atributos!$P$2:$W$5,4)*R3 -> 1 | V3: =+VLOOKUP(S3,Atributos!$P$2:$W$5,5)*R3 -> 8 | W3: =+VLOOKUP(S3,Atributos!$P$2:$W$5,6)*R3 -> 8 | X3: =+VLOOKUP(S3,Atributos!$P$2:$W$5,7)*R3 -> 8 | Y3: =+VLOOKUP(S3,Atributos!$P$2:$W$5,8)*R3 -> 0
A4: Finanzas | B4: Costos | C4: CO-02_Planificación de Ingresos, costos y gastos(CO_P010) | D4: 1HB | E4: Planificación de ingresos, costos y gastos, por centro de beneficio y centro de costos. Planificación de órdenes internas. | F4: Controlling permite planificar la estructura de costos y gastos de las futuras operaciones de la empresa para períodos determinados y efectuar comparaciones Real / Plan para su control. | G4: * Cargar diferentes Versione de planificación * Copiar de Real a Versión Plan * Copiar de Vérsión Plan a Versión Plan | H4: * El cálculo de planificación es por fuera de SAP * La planificación no es restrictiva solo informativa * Se puede planificar a nivel de ceco + clase de coste | I4: CO | J4: YS0_S4HANA_EO_001 YS0_S4HANA_EO_C001 | L4: Faltan roles. | M4: 1 | P4: 04 Terminado | R4: 1 | S4: PR | T4: =+VLOOKUP(S4,Atributos!$P$2:$W$5,3)*R4 -> 1 | U4: =+VLOOKUP(S4,Atributos!$P$2:$W$5,4)*R4 -> 2 | V4: =+VLOOKUP(S4,Atributos!$P$2:$W$5,5)*R4 -> 16 | W4: =+VLOOKUP(S4,Atributos!$P$2:$W$5,6)*R4 -> 32 | X4: =+VLOOKUP(S4,Atributos!$P$2:$W$5,7)*R4 -> 8 | Y4: =+VLOOKUP(S4,Atributos!$P$2:$W$5,8)*R4 -> 8
A5: Finanzas | B5: Costos | C5: CO-03_Control de Ingresos, costos y gastos(CO_P020) | D5: J54 | E5: Imputación real a cuentas de ingresos, costos y gastos. Gestión de órdenes internas de gastos y de inversión. Creación de ciclos de distribución y de subreparto. | F5: Comprende los distintos procesos por los cuales se registran imputaciones reales en las cuentas contables de costos, gastos, ingresos e inversión, ya sea por medio de centros de costos, centros de beneficio u órdenes internas. La ordenes internas son objetos de costos que se usan para identificar operaciones específicas y temporales con el fin de facilitar un análisis. Estas se aplican para controlar proyectos, campañas, obras en curso, etc. Los ciclos de distribución y/o subreparto sirven para distribuir o trasladar los costos de objetos de costos origen a objetos de costos destino. El ciclo de distribución traslada a través de la misma clase de costo, mientras el subreparto requiere de la clase de coste secundaria. | G5: * Imputaciones a cecos * Imputaciones a diferentes clase de Ordenes ( Inversión, reales , estadisticas) * Ciclos de distribución con diferentes metodos ( % , VE, Importe Fijo , etc) * Ciclos de Subreparto diferentes métodos ( % , VE , importe Fijo , Etc) | H5: * Los Drivers de los ciclos de distribución y subreparto no son automaticos ; si se define que el valor es mensual entonces se debe actualizar . * Todo objeto de costo con movimiento no puede ser eliminado. | I5: CO | J5: YS0_S4HANA_EO_001 YS0_S4HANA_EO_C001 | L5: Faltan roles. | M5: 1 | P5: 04 Terminado | R5: 1 | S5: PR | T5: =+VLOOKUP(S5,Atributos!$P$2:$W$5,3)*R5 -> 1 | U5: =+VLOOKUP(S5,Atributos!$P$2:$W$5,4)*R5 -> 2 | V5: =+VLOOKUP(S5,Atributos!$P$2:$W$5,5)*R5 -> 16 | W5: =+VLOOKUP(S5,Atributos!$P$2:$W$5,6)*R5 -> 32 | X5: =+VLOOKUP(S5,Atributos!$P$2:$W$5,7)*R5 -> 8 | Y5: =+VLOOKUP(S5,Atributos!$P$2:$W$5,8)*R5 -> 8
A6: Finanzas | B6: Costos | C6: CO-04_Análisis de Rentabilidad(CO_P040) | D6: J55 | E6: Definición características CO-PA. Subreparto de gastos. | F6: Es una herramienta que brinda SAP, para ayudar a las empresas a evaluar su rentabilidad mediante sus segmentos de mercado a partir de sus ventas, ganancias/pérdidas e información proveniente de otros módulos como finanzas, ventas y logística. Se tienen características como canal de ventas, línea de negocio, oficina de ventas, cliente, material, etc. dicha información puede ser analizada por periodos, ejercicio. | G6: * COPA - Análitico * COPA - Contable * Agregar caracteristicas Z* * Agregar caracteristicas despues de la activación de COPA * Ciclos de Subreparto de PA * Ejecución del TOP- DOW | H6: * COPA - Análitico ; existe la posibilidad que no cuadre exacto con la contabilidad ya que se usa para gestión * Los drivers del ciclo de subreparto no son automaticos . | I6: CO | J6: YS0_S4HANA_EO_001 YS0_S4HANA_EO_C001 | L6: Faltan roles. No hay flujo | M6: 1 | P6: 04 Terminado | R6: 1 | S6: PR | T6: =+VLOOKUP(S6,Atributos!$P$2:$W$5,3)*R6 -> 1 | U6: =+VLOOKUP(S6,Atributos!$P$2:$W$5,4)*R6 -> 2 | V6: =+VLOOKUP(S6,Atributos!$P$2:$W$5,5)*R6 -> 16 | W6: =+VLOOKUP(S6,Atributos!$P$2:$W$5,6)*R6 -> 32 | X6: =+VLOOKUP(S6,Atributos!$P$2:$W$5,7)*R6 -> 8 | Y6: =+VLOOKUP(S6,Atributos!$P$2:$W$5,8)*R6 -> 8
A7: Finanzas | B7: Costos | C7: CO-05_Reportes de Análisis(CO_P050) | D7: 4RC | E7: Reportes de Rentabilidad. Elaboración de reportes de gestión. Elaboración de estados financieros internos. | F7: Se refiere a los reportes de gastos por centros de costos, reportes de márgenes (por sociedad, unidad de negocio, etc.) y de estados financieros internos, por medio de la herramienta Report Painter. | H7: * Los reportes son Report Writer no se pueden transformar en ALV | I7: CO | J7: YS0_S4HANA_EO_001 YS0_S4HANA_EO_C001 | L7: Faltan roles. No hay flujo | M7: 1 | P7: 04 Terminado | R7: 1 | S7: RE | T7: =+VLOOKUP(S7,Atributos!$P$2:$W$5,3)*R7 -> 1 | U7: =+VLOOKUP(S7,Atributos!$P$2:$W$5,4)*R7 -> 2 | V7: =+VLOOKUP(S7,Atributos!$P$2:$W$5,5)*R7 -> 4 | W7: =+VLOOKUP(S7,Atributos!$P$2:$W$5,6)*R7 -> 16 | X7: =+VLOOKUP(S7,Atributos!$P$2:$W$5,7)*R7 -> 0 | Y7: =+VLOOKUP(S7,Atributos!$P$2:$W$5,8)*R7 -> 8
A8: Finanzas | B8: Cierre contable y financiero | C8: CO-06_Cierre de Controlling(CO_P060) | D8: J54 / BEV | E8: Análisis de ingresos en centros de beneficio. Análisis de costos y gastos en centros de costo y órdenes. Liquidación de ordenes internas. Ejecución de Distribución / Subreparto de gasto. | F8: En el cierre de Controlling, se tienen los siguientes eventos: - Análisis de ingresos en centros de beneficio: El proceso de análisis de los ingresos debe ser periodico durante el mes. - Análisis de costos y gastos en centros de costo y órdenes: El proceso de análisis de los costos y gastos deben ser periodicos durante el mes. - Liquidación de las ordenes internas: Las ordenes son acumuladores de gasto temporales por lo que en el cierre del periodo se debe realizar el proceso de liquidación con el objetivo que queden en cero. - Ejecución de distribución / subreparto de gasto: Este proceso comprende a las distribuciones de gastos operativos entre las unidades de negocio o según el modelo/criterio que determine la empresa. | I8: CO | J8: YS0_S4HANA_EO_001 YS0_S4HANA_EO_C001 | L8: Faltan roles. No hay flujo | M8: 1 | P8: 04 Terminado | R8: 1 | S8: PR | T8: =+VLOOKUP(S8,Atributos!$P$2:$W$5,3)*R8 -> 1 | U8: =+VLOOKUP(S8,Atributos!$P$2:$W$5,4)*R8 -> 2 | V8: =+VLOOKUP(S8,Atributos!$P$2:$W$5,5)*R8 -> 16 | W8: =+VLOOKUP(S8,Atributos!$P$2:$W$5,6)*R8 -> 32 | X8: =+VLOOKUP(S8,Atributos!$P$2:$W$5,7)*R8 -> 8 | Y8: =+VLOOKUP(S8,Atributos!$P$2:$W$5,8)*R8 -> 8
A9: Finanzas | B9: Costos | C9: CO-07_Costos de producción(CO_P030) | I9: CO | J9: YS0_S4HANA_EO_001 YS0_S4HANA_EO_C001 | M9: 2 | P9: 04 Terminado | R9: 1 | S9: PR | T9: =+VLOOKUP(S9,Atributos!$P$2:$W$5,3)*R9 -> 1 | U9: =+VLOOKUP(S9,Atributos!$P$2:$W$5,4)*R9 -> 2 | V9: =+VLOOKUP(S9,Atributos!$P$2:$W$5,5)*R9 -> 16 | W9: =+VLOOKUP(S9,Atributos!$P$2:$W$5,6)*R9 -> 32 | X9: =+VLOOKUP(S9,Atributos!$P$2:$W$5,7)*R9 -> 8 | Y9: =+VLOOKUP(S9,Atributos!$P$2:$W$5,8)*R9 -> 8
A10: Cadena de suministro | B10: EO | C10: EWM-00_Estructura organizativa(EWM_EO1) | E10: Número de almacén Tipos de almacén Áreas de almacenamiento | F10: Se detallan los niveles en los que se subdivide centro de distribución | I10: EWM | M10: 2 | P10: 04 Terminado | R10: 1 | S10: EO | T10: =+VLOOKUP(S10,Atributos!$P$2:$W$5,3)*R10 -> 1 | U10: =+VLOOKUP(S10,Atributos!$P$2:$W$5,4)*R10 -> 1 | V10: =+VLOOKUP(S10,Atributos!$P$2:$W$5,5)*R10 -> 4 | W10: =+VLOOKUP(S10,Atributos!$P$2:$W$5,6)*R10 -> 4 | X10: =+VLOOKUP(S10,Atributos!$P$2:$W$5,7)*R10 -> 0 | Y10: =+VLOOKUP(S10,Atributos!$P$2:$W$5,8)*R10 -> 0
A11: Cadena de suministro | B11: Gestión de datos maestros | C11: EWM-01_Administración de Datos Maestros(EWM_M010) | E11: Ampliación de materiales: Indicadores de tipo de almacén Indicadores de área de almacenamiento | F11: Se actualiza la información del material para colocarle los indicadores correspondientes a ingreso y salida. | I11: EWM | M11: 2 | P11: 04 Terminado | R11: 1 | S11: DM | T11: =+VLOOKUP(S11,Atributos!$P$2:$W$5,3)*R11 -> 1 | U11: =+VLOOKUP(S11,Atributos!$P$2:$W$5,4)*R11 -> 1 | V11: =+VLOOKUP(S11,Atributos!$P$2:$W$5,5)*R11 -> 8 | W11: =+VLOOKUP(S11,Atributos!$P$2:$W$5,6)*R11 -> 8 | X11: =+VLOOKUP(S11,Atributos!$P$2:$W$5,7)*R11 -> 8 | Y11: =+VLOOKUP(S11,Atributos!$P$2:$W$5,8)*R11 -> 0
A12: Cadena de suministro | B12: Almacenamianto | C12: EWM-02_Procesos de entrada (EWM_P010) | D12: 1FS | E12: Orden de compra o ingreso directo: Generación de la entrega entrante Modificación de la entrega/contabilización Creación de la orden de almacén Confirmación de de la orden | F12: El proceso de ingreso permite brindar soporte a las actividades ejecutadas desde la recepción de la mercadería hasta la colocación de los materiales en la ubicación final | G12: - Ingreso por compra - Ingreso directo sin pedido - Ingreso por traslado | I12: EWM | M12: 2 | P12: 04 Terminado | R12: 1 | S12: PR | T12: =+VLOOKUP(S12,Atributos!$P$2:$W$5,3)*R12 -> 1 | U12: =+VLOOKUP(S12,Atributos!$P$2:$W$5,4)*R12 -> 2 | V12: =+VLOOKUP(S12,Atributos!$P$2:$W$5,5)*R12 -> 16 | W12: =+VLOOKUP(S12,Atributos!$P$2:$W$5,6)*R12 -> 32 | X12: =+VLOOKUP(S12,Atributos!$P$2:$W$5,7)*R12 -> 8 | Y12: =+VLOOKUP(S12,Atributos!$P$2:$W$5,8)*R12 -> 8
A13: Cadena de suministro | B13: Almacenamianto | C13: EWM-03_Procesos de salida (EWM_P020) | D13: 1G2 | E13: Pedido de venta o salida directa: Generación de la entrega de salida Creación de la orden de almacén Confirmación de de la orden Contabilización de la entrega de salida | F13: El proceso de salida permite brindar soporte a las actividades ejecutadas desde la extracción de la recepción de la mercadería hasta la colocación de los materiales en la ubicación final | G13: -Salida por venta -Salida por consumo directo -Salida por traslado | I13: EWM | M13: 2 | P13: 04 Terminado | R13: 1 | S13: PR | T13: =+VLOOKUP(S13,Atributos!$P$2:$W$5,3)*R13 -> 1 | U13: =+VLOOKUP(S13,Atributos!$P$2:$W$5,4)*R13 -> 2 | V13: =+VLOOKUP(S13,Atributos!$P$2:$W$5,5)*R13 -> 16 | W13: =+VLOOKUP(S13,Atributos!$P$2:$W$5,6)*R13 -> 32 | X13: =+VLOOKUP(S13,Atributos!$P$2:$W$5,7)*R13 -> 8 | Y13: =+VLOOKUP(S13,Atributos!$P$2:$W$5,8)*R13 -> 8
A14: Cadena de suministro | B14: Almacenamianto | C14: EWM-04_Procesos internos (EWM_P030) | D14: 1V5 | E14: Cambio de ubicación individual Cambio de ubicaión masivo Cambio de tipo de stock | F14: Los procesos dentro del almacén pueden ser mapeados a detalle en el sistema para reflejar los cambios de ubicación y/o tipos de stock | G14: -Cambio de ubicación individual -Cambio de ubicación masivo -Cambio de tipo de stock | I14: EWM | M14: 2 | P14: 04 Terminado | R14: 1 | S14: PR | T14: =+VLOOKUP(S14,Atributos!$P$2:$W$5,3)*R14 -> 1 | U14: =+VLOOKUP(S14,Atributos!$P$2:$W$5,4)*R14 -> 2 | V14: =+VLOOKUP(S14,Atributos!$P$2:$W$5,5)*R14 -> 16 | W14: =+VLOOKUP(S14,Atributos!$P$2:$W$5,6)*R14 -> 32 | X14: =+VLOOKUP(S14,Atributos!$P$2:$W$5,7)*R14 -> 8 | Y14: =+VLOOKUP(S14,Atributos!$P$2:$W$5,8)*R14 -> 8
A15: Cadena de suministro | B15: Almacenamianto | C15: EWM-05_Inventario (EWM_P040) | D15: 1V7 | E15: Toma de inventario por material Toma de inventario por ubicación | F15: Proceso de conteo de materiales y/o ubicaciones con mayor precisión | G15: -Toma de inventario por material sin diferencia -Tomoa de inventario por ubicación con diferencia | I15: EWM | M15: 2 | P15: 04 Terminado | R15: 1 | S15: PR | T15: =+VLOOKUP(S15,Atributos!$P$2:$W$5,3)*R15 -> 1 | U15: =+VLOOKUP(S15,Atributos!$P$2:$W$5,4)*R15 -> 2 | V15: =+VLOOKUP(S15,Atributos!$P$2:$W$5,5)*R15 -> 16 | W15: =+VLOOKUP(S15,Atributos!$P$2:$W$5,6)*R15 -> 32 | X15: =+VLOOKUP(S15,Atributos!$P$2:$W$5,7)*R15 -> 8 | Y15: =+VLOOKUP(S15,Atributos!$P$2:$W$5,8)*R15 -> 8
A16: Finanzas | B16: EO | C16: FI-00_Estructura Organizativa(FI_EO1) | E16: Sociedad FI Variante de ejercicio Variante de periodos Plan de cuentas Clase de cuentas Definición de monedas Clases de documentos Claves de contabilización Documento financiero Tipo de cambio Ledgers paralelos Sociedad GL | F16: La estructura organizativa representa la vista jurídica u organizativa de la empresa y corresponde a un requisito esencial tanto para la determinación de los datos maestros, como para los procesos a definir en la empresa. Asi mismo, abarca la definción de conceptos escenciales para dar soporte a los procesos contables. Por ejemplo, conceptos como: las Clases de documento, variante de ejercicio, variante de periodos, Claves de contabiización y otros. | G16: - Las Sociedades FI pueden estar sujetas a alguna caracteristicas desde su creación por ejemplo: a) Plan de Cuentas Operativo y Plan de Cuentas País ( Se define en Base a la Sociedad Matriz o Grupo ) | H16: "Revalorización en modena extranjera" Caso que se generea ingreso o gasto que de manera automática se imputa a un cebe o ceco. | I16: FI | J16: YS0_S4HANA_EO_001 YS0_S4HANA_EO_C001 | M16: 1 | N16: ANEXO_FI01 - Clases de documentos | P16: 04 Terminado | R16: 1 | S16: EO | T16: =+VLOOKUP(S16,Atributos!$P$2:$W$5,3)*R16 -> 1 | U16: =+VLOOKUP(S16,Atributos!$P$2:$W$5,4)*R16 -> 1 | V16: =+VLOOKUP(S16,Atributos!$P$2:$W$5,5)*R16 -> 4 | W16: =+VLOOKUP(S16,Atributos!$P$2:$W$5,6)*R16 -> 4 | X16: =+VLOOKUP(S16,Atributos!$P$2:$W$5,7)*R16 -> 0 | Y16: =+VLOOKUP(S16,Atributos!$P$2:$W$5,8)*R16 -> 0
A17: Finanzas | B17: Gestión de datos maestros | C17: FI-01_Maestro de Contabilidad General(FI_M010) | D17: J58-01 | E17: Plan de cuentas Operativo -Segmento de Plan de Cuentas -Segmento de Sociedad Reportes | F17: El maestro del Plan de Cuentas, agrupa la totalidad de las cuentas de mayor de la organización. En SAP, una sociedad puede gestionar tres planes de cuentas: - Plan de cuentas operativo (es indispensable). - Plan de cuentas de grupo. - Plan de cuentas del país | G17: 1) Manejar en la Sociedad solo con el Plan Contable Operativo ( ejemplo :PCGE ) 2) Manejar en la Sociedad Plan Contable Operativo y Alternativo ( ejemplo : CAPE (Opeativo ) y Alternativo PCGE ( Local ) 3) Opcional manejar Plan de Cuenta Grupo | I17: FI | J17: YS0_S4HANA_EO_001 YS0_S4HANA_EO_C001 | L17: Faltan app y roles | M17: 1 | O17: MC_FI_M010 - Plan de cuentas | P17: 04 Terminado | R17: 1 | S17: DM | T17: =+VLOOKUP(S17,Atributos!$P$2:$W$5,3)*R17 -> 1 | U17: =+VLOOKUP(S17,Atributos!$P$2:$W$5,4)*R17 -> 1 | V17: =+VLOOKUP(S17,Atributos!$P$2:$W$5,5)*R17 -> 8 | W17: =+VLOOKUP(S17,Atributos!$P$2:$W$5,6)*R17 -> 8 | X17: =+VLOOKUP(S17,Atributos!$P$2:$W$5,7)*R17 -> 8 | Y17: =+VLOOKUP(S17,Atributos!$P$2:$W$5,8)*R17 -> 0
A18: Finanzas | B18: Gestión de datos maestros | C18: FI-02_Maestro de Activos Fijos(FI_M020) | D18: J62-01 | E18: Maestro de Activos Fijos | F18: El maestro de activos fijos centraliza la administración de los activos fijos mediante la creación y mantenimiento de códigos únicos de AF. Bajos los cuales se contabilizan las altas, bajas, traslados, depreciación u otras operaciones. Los códigos de activos fijos dan soporte a los procesos de activos fijos y permite un análisis contable por código de activo. | G18: 1) Manejar diferentes Areas de Valoración para su tratamiento Contable,Tributario o de Revaluaciones 2) Manejar diferentes tipos de Clave de Amortización : Ejemplo Lineal o por Unidades Producidas. 3) Llevar el control de las Altas, Bajas y traspasos de las diferentes clases de activos dependiendo de sus Vida Utiles | I18: FI | J18: YS0_S4HANA_FIAA_001 | K18: YS0_S4HANA_EO_001 YS0_S4HANA_EO_C001 | L18: Faltan app y roles | M18: 1 | N18: ANEXO_FI06 - Clases de Activos Fijos | O18: MC_FI_M020 - Maestro de Activos Fijos | P18: 04 Terminado | R18: 1 | S18: DM | T18: =+VLOOKUP(S18,Atributos!$P$2:$W$5,3)*R18 -> 1 | U18: =+VLOOKUP(S18,Atributos!$P$2:$W$5,4)*R18 -> 1 | V18: =+VLOOKUP(S18,Atributos!$P$2:$W$5,5)*R18 -> 8 | W18: =+VLOOKUP(S18,Atributos!$P$2:$W$5,6)*R18 -> 8 | X18: =+VLOOKUP(S18,Atributos!$P$2:$W$5,7)*R18 -> 8 | Y18: =+VLOOKUP(S18,Atributos!$P$2:$W$5,8)*R18 -> 0
A19: Finanzas | B19: Gestión de tesorería | C19: FI-03_Maestro de bancos(FI_M030) | D19: BFA | E19: Maestro de Bancos Bancos propios Cuentas bancarias | F19: Con la gestión de cuentas bancarias el área de tesorería puede centralizar la gestión de cuentas bancarias utilizando los datos maestros de cuentas bancarias. | G19: 1) Crear Bancos País 2) Crear Bancos Propios 3) Crear Cuentas Bancarias de Bancos Propios. | I19: FI | J19: YS0_S4HANA_EO_001 YS0_S4HANA_EO_C001 | L19: Faltan app y roles | M19: 1 | N19: ANEXO_FI07 - Bancos propios y cuentas bancarias ANEXO_FI09 - Claves de bancos | O19: MC_FI_M030 - Maestro de bancos | P19: 04 Terminado | R19: 1 | S19: DM | T19: =+VLOOKUP(S19,Atributos!$P$2:$W$5,3)*R19 -> 1 | U19: =+VLOOKUP(S19,Atributos!$P$2:$W$5,4)*R19 -> 1 | V19: =+VLOOKUP(S19,Atributos!$P$2:$W$5,5)*R19 -> 8 | W19: =+VLOOKUP(S19,Atributos!$P$2:$W$5,6)*R19 -> 8 | X19: =+VLOOKUP(S19,Atributos!$P$2:$W$5,7)*R19 -> 8 | Y19: =+VLOOKUP(S19,Atributos!$P$2:$W$5,8)*R19 -> 0
A20: Finanzas | B20: Contabilidad | C20: FI-04_Contabilidad General(FI_P010) | D20: J58-03 J58-04 | E20: Registro de Asientos de Diario Registro de Asientos de provisiones Asientos periódicos Anulación de registros Desglose de documentos Reportes | F20: En SAP S/4HANA este proceso proporciona soporte a la gestión de la información financiera referida a la evaluación y generación de los reportes de resultados y de cuentas de balance. Por lo que, permite la emisión de documentos de contabilidad general, como asientos diarios o asientos periódicos. | G20: 1) Provisiones y Extornos ( Afectos o Inafectos ) 2) Reclasificaciones 2) Asientos Periodicos por concepto de Alquileres 3) Anulaciones de documentos. | I20: FI | J20: YS0_S4HANA_EO_001 YS0_S4HANA_EO_C001 | M20: 1 | P20: 04 Terminado | R20: 1 | S20: PR | T20: =+VLOOKUP(S20,Atributos!$P$2:$W$5,3)*R20 -> 1 | U20: =+VLOOKUP(S20,Atributos!$P$2:$W$5,4)*R20 -> 2 | V20: =+VLOOKUP(S20,Atributos!$P$2:$W$5,5)*R20 -> 16 | W20: =+VLOOKUP(S20,Atributos!$P$2:$W$5,6)*R20 -> 32 | X20: =+VLOOKUP(S20,Atributos!$P$2:$W$5,7)*R20 -> 8 | Y20: =+VLOOKUP(S20,Atributos!$P$2:$W$5,8)*R20 -> 8
A21: Finanzas | B21: Operaciones financieras | C21: FI-05_Cuentas por Pagar(FI_P020) | D21: J60 | E21: Maestro de Interlocutor Comercial (Acreedores o Proveedores) Registro de Facturas y otros Comprobantes de Proveedor - Registro de Comprobantes por Finanzas (FI) - Registro de Comprobantes Con Orden de Compra (MM) Indicadores de impuestos Compras Percepciones por compra Registro de Comprobantes de Importación de bienes Registro de IGV no domiciliado Solicitudes de Anticipo Acreedor Retenciones en la factura - Detracciones de IGV - Retenciones no Domiciliados - Retenciones dietas Retenciones en el pago - Retenciones de IGV - Retenciones de 4ta categoría Anulación de Registro Registros preliminares Cuenta de mayor especial (CME) Compensaciones - Con anticipos - Con N/D y N/C - Canje de letras - Factura Negociable o Factoring o Compensación Deudor/Acreedor o Anulación de compensación Reportes | F21: El proceso de cuentas por pagar comprende básicamente la contabilidad en acreedores producto de las operaciones de adquisición de bienes o servicios que generen una obligación de pago. Los acreedores cuentan con un código único en el maestro de Business Partner bajo el cual se registran sus operaciones y permiten el análisis auxiliar por cuenta acreedora. Así mismo se contabilizan facturas y abonos, se registran pagos y anticipos, se gestionan los valores entregados como medios de pago y al contabilizar datos en acreedores, el sistema crea un documento contable y transfiere los datos introducidos al libro mayor y según corresponda al Libro de Compras. | G21: 1) Registro de Comprobantes por Finanzas ( Todos los documentos SUNAT ) 2) Registro de Comprobantes usando los diferentes tipos de Indicadores de Impuestos. 3) Registro de FActura de No Domiciliado , Provisión IGV No Domiciliado y Extorno provisión IGV 4) Registro de Formulario de Declaración - pago o Boleta de pago de tributos Internos 5) Generar Solicitudes de Anticipo y su respectiva Contabilización. 6) Anulaciones de Registros o Comprobantes 7) Creación de documentos preliminares antes de su contabilización 8) Redireccionamiento de Cuentas a través del uso del CME 9) Compensaciones Parciales o Totales de la cuentas por pagar. Letras, Factura Negociable y Facttoring 10) Compensaciones entre Deudores(CXC) y Acreedores ( CXP) 11) Descompesación de documentos de pago | H21: Los indicadores de impuestos están asociado al IGV. No está considerado otro tipo de impuesto como ISC, impuestos especiales de sectores industriales, FISE, Rodamiento, impuestos a los plásticos, etc | I21: FI | J21: YS0_S4HANA_EO_001 YS0_S4HANA_EO_C001 | M21: 1 | N21: ANEXO_FI05 - CME ANEXO_FI10 - Retenciones | P21: 04 Terminado | R21: 1 | S21: PR | T21: =+VLOOKUP(S21,Atributos!$P$2:$W$5,3)*R21 -> 1 | U21: =+VLOOKUP(S21,Atributos!$P$2:$W$5,4)*R21 -> 2 | V21: =+VLOOKUP(S21,Atributos!$P$2:$W$5,5)*R21 -> 16 | W21: =+VLOOKUP(S21,Atributos!$P$2:$W$5,6)*R21 -> 32 | X21: =+VLOOKUP(S21,Atributos!$P$2:$W$5,7)*R21 -> 8 | Y21: =+VLOOKUP(S21,Atributos!$P$2:$W$5,8)*R21 -> 8
A22: Finanzas | B22: Operaciones financieras | C22: FI-06_Otras Cuentas por Pagar(FI_P021) | D22: J60 | E22: Registro de otras Cuentas por Pagar (Prestamos con terceros o vinculadas, Pagares, Financiamientos, Cuotas de Leasing) Impuestos Caja Chica - Constitución de Caja Chica por medio de anticipo. - Registro de Facturas y otros Comprobantes de Proveedor - Liquidación de documentos - Reposición de Caja Chica Entregas a Rendir - Solicitud (anticipo) - Registro de Salidas a Rendir (Pago a colaborador) - Registro de facturas - Liquidación de Gastos Desembolsos - Registro de facturas por pagar - Compensación de facturas por pagar contra cuenta por pagar al trabajador - Reposición al trabajador Tarjetas de crédito empresariales - Registro de facturas por pagar - Compensación de comprobantes de pago contra cuenta de tarjetas de crédito - Registro de cuenta tarjetas de crédito contra cuenta bancos Reportes | F22: El proceso de Otras cuentas por pagar abarca el registro en acreedores de operaciones no core de negocio. Tales como financiamientos, impuestos, entredas a rendir, caja chica. | G22: 1) Generar documentos por Préstamos a Terceros o Vinculadas 2) Generar documentos por Obligaciones Bancarias ( Pagarés ); incluyendo sus amortizaciones y cancelaciones 3) Generar documentos por Financiamientos con Bancos; incluyendo sus amortizaciones y cancelaciones. 4) Registros de Cuotas de Leasing ( Devengamiento incluyendo Intereses ). 5) Registar los impuestos por Pagar ( IGV) contra la SUNAT. 6) Registro, liquidación y reposición Caja Chica 7) Permite registrar Solicitud de Entregas a Rendir, registros de comprobantes y liquidación. 8) Registrar Desembolsos a Empleados por gestionar compras menores a nombre de la Empresa. Registrar comprobante y reposición del dinero al Empleado. 9) Permitir liquidaciones de tarjetas de crédito empresarial contra los comprobantes incurridos. | H22: Los indicadores de impuestos están asociado al IGV. No está considerado otro tipo de impuesto como ISC, impuestos especiales de sectores industriales, FISE, Rodamiento, impuestos a los plásticos, etc | I22: FI | J22: YS0_S4HANA_EO_001 YS0_S4HANA_EO_C001 | M22: 1 | N22: ANEXO_FI05 - CME | P22: 04 Terminado | R22: 1 | S22: PR | T22: =+VLOOKUP(S22,Atributos!$P$2:$W$5,3)*R22 -> 1 | U22: =+VLOOKUP(S22,Atributos!$P$2:$W$5,4)*R22 -> 2 | V22: =+VLOOKUP(S22,Atributos!$P$2:$W$5,5)*R22 -> 16 | W22: =+VLOOKUP(S22,Atributos!$P$2:$W$5,6)*R22 -> 32 | X22: =+VLOOKUP(S22,Atributos!$P$2:$W$5,7)*R22 -> 8 | Y22: =+VLOOKUP(S22,Atributos!$P$2:$W$5,8)*R22 -> 8
A23: Finanzas | B23: Contabilidad | C23: FI-07_Pago a Proveedores(FI_P022) | D23: J60-05 J60-06 | E23: Anticipo a Proveedores Pago Individuales y Masivos - Con nota de crédito (aplicación) - Con Cheque - Con Transferencia Electrónica - Pagos Interbancarios Pago de Planillas de RRHH Pagos Parciales Retenciones en el pago Anulación de pagos Vías de pago Bloqueos de pago Condición de pago Reportes | F23: El proceso de pago a proveedores abarca los diferentes mecanismos y condiciones que el modulo FI ofrece para contabilzar los pagos sobre los registros previamente generados en el proceso de cuentas por pagar. | G23: 1) Generar Solicitudes de Anticipos para la Caja Chica, Entregas a Rendir y Anticipos a Terceros 2) Pagos Individuales o Masivos a Proveedores. Aplicando pagos parciales o totales. 3) Registrar documentos que estan sujetos a Retenciones sea en el documento o en el Pago ( Localización ) 4) Registrar las anulaciones de las compensaciones por los documentos de pago. | I23: FI | J23: YS0_S4HANA_EO_001 YS0_S4HANA_EO_C001 | M23: 1 | N23: ANEXO_FI08 - Condiciones de pago | P23: 04 Terminado | R23: 1 | S23: PR | T23: =+VLOOKUP(S23,Atributos!$P$2:$W$5,3)*R23 -> 1 | U23: =+VLOOKUP(S23,Atributos!$P$2:$W$5,4)*R23 -> 2 | V23: =+VLOOKUP(S23,Atributos!$P$2:$W$5,5)*R23 -> 16 | W23: =+VLOOKUP(S23,Atributos!$P$2:$W$5,6)*R23 -> 32 | X23: =+VLOOKUP(S23,Atributos!$P$2:$W$5,7)*R23 -> 8 | Y23: =+VLOOKUP(S23,Atributos!$P$2:$W$5,8)*R23 -> 8
A24: Finanzas | B24: Operaciones financieras | C24: FI-08_Cuentas Por Cobrar(FI_P030) | D24: J59 | E24: Maestro de Interlocutor Comercial (Deudores o Clientes) Registro de Facturas y otros Comprobantes de Clientes - Registro de Comprobantes por Finanzas (FI) - Registro de Comprobantes Con Pedido Venta(SD) Indicadores de impuestos Ventas Percepciones Venta Registro de Comprobantes de Importación de bienes Registro de IGV no domiciliado Solicitudes de Anticipo Acreedor Retenciones en la factura - Detracciones de IGV - Retenciones no Domiciliados - Retenciones dietas Retenciones en el pago - Retenciones de IGV - Retenciones de 4ta categoría Anulación de Registro Registros preliminares Cuenta de mayor especial (CME) Compensaciones - Con anticipos - Con N/D y N/C - Canje de letras - Factura Negociable o Factoring o Compensación Deudor/Acreedor o Anulación de compensación Reportes | F24: El proceso de cuentas por cobrar comprende básicamente la contabilidad en deudores producto de las operaciones de venta de bienes o servicios que generen una obligación de cobro. Los clientes cuentan con un código único en el maestro de Business Partner bajo el cual se registran sus operaciones y permiten el análisis auxiliar por cuenta deudora. | G24: 1) Registrar Comprobantes de Ventas por FI ( Facturas , Notas de Crédito y Débito ) con sus indicadores de IVA 2) Registrar Provisiones de Ingresos por FI 3) Registrar documentos por Provisión de Cobranza Dudosa 4) Registrar préstamos entre Empresas Vinculadas o Terceros 5) Registro de Otras de Cuentas por Cobrar Diversas 6) Registrar Retenciones en la cuentas por Cobrar en el momento de la contabilización de la factura ( Localización ). Manejando Percepción de Venta y Detracción de Venta. 7) Anulación del documento de venta generado 9) Compensación de Partidas Deudoras, Anticipos, Notas de Crédito y Débito. 10) Compensación de Deudores con Acreedores 11) Anulación o descompnesación de documentos de cobro. | H24: Los indicadores de impuestos están asociado al IGV. No está considerado otro tipo de impuesto como ISC, impuestos especiales de sectores industriales, FISE, Rodamiento, impuestos a los plásticos, etc | I24: FI | J24: YS0_S4HANA_EO_001 YS0_S4HANA_EO_C001 | M24: 1 | N24: ANEXO_FI05 - CME | P24: 04 Terminado | R24: 1 | S24: PR | T24: =+VLOOKUP(S24,Atributos!$P$2:$W$5,3)*R24 -> 1 | U24: =+VLOOKUP(S24,Atributos!$P$2:$W$5,4)*R24 -> 2 | V24: =+VLOOKUP(S24,Atributos!$P$2:$W$5,5)*R24 -> 16 | W24: =+VLOOKUP(S24,Atributos!$P$2:$W$5,6)*R24 -> 32 | X24: =+VLOOKUP(S24,Atributos!$P$2:$W$5,7)*R24 -> 8 | Y24: =+VLOOKUP(S24,Atributos!$P$2:$W$5,8)*R24 -> 8
A25: Finanzas | B25: Tesoreria | C25: FI-09_Gestión de Tesorería(FI_P040) | D25: 4X8 | E25: Operaciones de Tesorería - Transferencia entre Cuentas - Compra/Venta de Divisas Reportes | F25: La Gestión de Tesorería, abarca el registro de las operaciones propias a la administración de los fondos de la empresa. | G25: 1) Gestionar Transferencia Bancarias 2) Registrar Compra / Venta de Divisas 3) Cobranzas | I25: FI | J25: YS0_S4HANA_EO_001 YS0_S4HANA_EO_C001 | M25: 1 | P25: 04 Terminado | R25: 1 | S25: PR | T25: =+VLOOKUP(S25,Atributos!$P$2:$W$5,3)*R25 -> 1 | U25: =+VLOOKUP(S25,Atributos!$P$2:$W$5,4)*R25 -> 2 | V25: =+VLOOKUP(S25,Atributos!$P$2:$W$5,5)*R25 -> 16 | W25: =+VLOOKUP(S25,Atributos!$P$2:$W$5,6)*R25 -> 32 | X25: =+VLOOKUP(S25,Atributos!$P$2:$W$5,7)*R25 -> 8 | Y25: =+VLOOKUP(S25,Atributos!$P$2:$W$5,8)*R25 -> 8
A26: Finanzas | B26: Cierre contable y financiero | C26: FI-10_Gestión de Activos Fijos(FI_P050) | D26: J62 | E26: Alta de Activos Fijos - Por Compra directa - Por Adquisición bajo arrendamiento financiero. - Por liquidación de obra en curso Traslados Baja de Activos Fijos - Por venta - Por desguace Activos mantenidos para la venta Revaluación y Desvalorización Depreciación Operaciones de Cierre Anual Reportes | F26: Este proceso comprende las diferentes operaciones contables que se registran sobre los activos fijos. Así mismo, abarca la reportería para el análisis contable de los activos fijos. | G26: 1) Alta de Activos por Compras o Liquidaciones de Activos en Curso. 2) Alta de Activos por Arrendamiento Financiero desde FI. 3) Traspasos de Activos 4) Bajas de Activos: Baja por Desguace / Baja por Venta 5) Revaluaciones de Activos Fijos 6) Ejecución de las Depreciaciones 7) Cambio de Ejercicio y Cierre de Ejercicio de Activos Fijos | I26: FI | J26: YS0_S4HANA_FIAA_001 | K26: YS0_S4HANA_EO_001 YS0_S4HANA_EO_C001 | L26: Faltan app y roles | M26: 1 | P26: 04 Terminado | R26: 1 | S26: PR | T26: =+VLOOKUP(S26,Atributos!$P$2:$W$5,3)*R26 -> 1 | U26: =+VLOOKUP(S26,Atributos!$P$2:$W$5,4)*R26 -> 2 | V26: =+VLOOKUP(S26,Atributos!$P$2:$W$5,5)*R26 -> 16 | W26: =+VLOOKUP(S26,Atributos!$P$2:$W$5,6)*R26 -> 32 | X26: =+VLOOKUP(S26,Atributos!$P$2:$W$5,7)*R26 -> 8 | Y26: =+VLOOKUP(S26,Atributos!$P$2:$W$5,8)*R26 -> 8
A27: Finanzas | B27: Cierre contable y financiero | C27: FI-11_Cierre Contable(FI_P100) | D27: J58-01 | E27: Proceso de Cierre de Mes - Registro de documentos - Apertura y Cierre de Períodos contables - Desplazamiento de periodo logístico - Anulación de documentos FI - Análisis y Compensación de cuentas - Conciliación bancaria - Valoración de Moneda Extranjera - Traslación - Liquidación de AFeC - Depreciación/Amortización de activos fijos o intangibles Proceso de Cierre de Año - Arrastre de Saldos Anual - Cierre de ejercicio de Activos Fijos Estados Financieros y libros oficiales Reportes | F27: Este proceso se encuentra constituido por las actividades que permiten cerrar las operaciones necesarias del día, mes y del ejercicio. Para ello, el sistema ofrece un conjunto de programas que permiten ejecutar los procesos de cierre y hacer análisis a través reportes de resultados y de cuentas balance. | G27: 1) Apertura y Cierre periodos contables( Variante de Ejercicio FI) 2) Desplazamiento de Periodo Logistico. 3) Compensaciones Manuales o Automaticas de Cuentas de Mayor 4) Conciliación Banacaria ( Localización ) 5) Valoración de Moneda Extranjera ( Ejemplo: USD a PEN ) 6) Traslasión Moneda Local ( Ejemplo PEN a USD ) 7) Liquidación de Activos FIjo en Curso 8) Ejecución de la Depreciaión del mes correspondiente. 9) Arrastre de Saldos que incluye la apertura del nuevo ejercicio para Activos Fijos. 10) Cierre de Ejercicio de Activos Fijos 11) Reporteria Balance General o Report Painters 12) Libros Electrónicos SUNAT ( Localización Z) | I27: FI | J27: YS0_S4HANA_EO_001 YS0_S4HANA_EO_C001 | M27: 1 | P27: 04 Terminado | R27: 1 | S27: PR | T27: =+VLOOKUP(S27,Atributos!$P$2:$W$5,3)*R27 -> 1 | U27: =+VLOOKUP(S27,Atributos!$P$2:$W$5,4)*R27 -> 2 | V27: =+VLOOKUP(S27,Atributos!$P$2:$W$5,5)*R27 -> 16 | W27: =+VLOOKUP(S27,Atributos!$P$2:$W$5,6)*R27 -> 32 | X27: =+VLOOKUP(S27,Atributos!$P$2:$W$5,7)*R27 -> 8 | Y27: =+VLOOKUP(S27,Atributos!$P$2:$W$5,8)*R27 -> 8
A28: Finanzas | B28: Operaciones financieras avanzadas | C28: FI-12_Gestión de Créditos(SD_P070) | D28: BD6 | E28: Área de control de crédito Segmento de crédito Asignación de la línea de crédito Consumo de la línea de crédito Reportes | F28: Corresponden a los datos que contienen información relevante para la gestión de créditos, funcionalidades para su seguimiento y control. Si la empresa trabaja con líneas de crédito para los clientes, se determina en que procesos de venta aplica este proceso. Al realizar el pedido de venta se verifica si hay deuda vencida y si el pedido sobrepasa la línea de crédito asignada. | G28: Venta Nacional con límite de crédito excedido. Venta Exportación con partidas abiertas vencidas. Venta Servicios con suficiente línea de crédito. | I28: SD | J28: YS0_S4HANA_SD_001 YS0_S4HANA_SD_C001 | K28: YS0_S4HANA_EO_001 YS0_S4HANA_EO_C001 | L28: Falta establecer el flujo adecuado para el proceso, transacciones en el paso a paso del BPD | M28: 1 | P28: 04 Terminado | R28: 1 | S28: PR | T28: =+VLOOKUP(S28,Atributos!$P$2:$W$5,3)*R28 -> 1 | U28: =+VLOOKUP(S28,Atributos!$P$2:$W$5,4)*R28 -> 2 | V28: =+VLOOKUP(S28,Atributos!$P$2:$W$5,5)*R28 -> 16 | W28: =+VLOOKUP(S28,Atributos!$P$2:$W$5,6)*R28 -> 32 | X28: =+VLOOKUP(S28,Atributos!$P$2:$W$5,7)*R28 -> 8 | Y28: =+VLOOKUP(S28,Atributos!$P$2:$W$5,8)*R28 -> 8
A29: Abastecimiento y compras | B29: EO | C29: MM-00_Estructura organizativa(MM_EO1) | E29: Sociedad Organización de Compra Grupo de Compra Centros Almacén | F29: En la estructura SAP S/4HANA se representa la vista jurídica u organizativa de una empresa como los niveles de la organización. La determinación de dichos niveles constituye la Estructura Organizativa y corresponde, a un requisito escencial tanto para la determinación de los datos maestros como para los procesos a definir en la empresa. | I29: MM | J29: YS0_S4HANA_EO_001 YS0_S4HANA_EO_C001 | M29: 1 | P29: 04 Terminado | R29: 1 | S29: EO | T29: =+VLOOKUP(S29,Atributos!$P$2:$W$5,3)*R29 -> 1 | U29: =+VLOOKUP(S29,Atributos!$P$2:$W$5,4)*R29 -> 1 | V29: =+VLOOKUP(S29,Atributos!$P$2:$W$5,5)*R29 -> 4 | W29: =+VLOOKUP(S29,Atributos!$P$2:$W$5,6)*R29 -> 4 | X29: =+VLOOKUP(S29,Atributos!$P$2:$W$5,7)*R29 -> 0 | Y29: =+VLOOKUP(S29,Atributos!$P$2:$W$5,8)*R29 -> 0
A30: Abastecimiento y compras | B30: Gestión de datos maestros | C30: MM-01_Maestro de materiales(MM_M010) | E30: Niveles de organización Agrupación de Materiales Gestión de Valoración Vistas de Información - Datos básicos - Datos de compras - Datos de ventas - Datos de planificación - Datos de centro/almacén - Datos contables Reportes | F30: En SAP S/4HANA el maestro de materiales es el más importante repositorio de información base para todos los procesos logísticos y de gestión de stocks. Aquí se administran todos los datos de los materiales gestionados por la organización. El maestro de materiales está estructurado en “vistas” o pestañas de datos. Cada vista contiene campos específicos relacionados a un área funcional o proceso de negocio. Si a un material no se le ha completado correctamente las vistas vinculadas a un proceso, este material no podrá ser utilizado en dichos procesos. | G30: Tipo de Material: -Mercadería -Materia Prima -Material no valorado -Suministros -Embalajes -Producto semielaborado -Producto Terminado -Material Servicios | H30: Se excluye campos no mencionados en el BPD. | I30: MM | K30: YS0_S4HANA_EO_001 YS0_S4HANA_EO_C001 | L30: Deacuerdo a las best practice de SAP, el maestro de servicios (Tx. AC01/AC02/AC03) se reemplazará por la utilización del tipo de material ‘SERV‘ para los servicios que se compran y venden. | M30: 1 | N30: ANEXO_MM01 - Grupo de artículos ANEXO_MM02 - Categoría de valoración ANEXO_MM03 - Planificadores de necesidad ANEXO_MM05 - Jerarquía de productos ANEXO_MM08 - OBYC | O30: MC_MM_M010 - Maestro de materiales | P30: 04 Terminado | R30: 1 | S30: DM | T30: =+VLOOKUP(S30,Atributos!$P$2:$W$5,3)*R30 -> 1 | U30: =+VLOOKUP(S30,Atributos!$P$2:$W$5,4)*R30 -> 1 | V30: =+VLOOKUP(S30,Atributos!$P$2:$W$5,5)*R30 -> 8 | W30: =+VLOOKUP(S30,Atributos!$P$2:$W$5,6)*R30 -> 8 | X30: =+VLOOKUP(S30,Atributos!$P$2:$W$5,7)*R30 -> 8 | Y30: =+VLOOKUP(S30,Atributos!$P$2:$W$5,8)*R30 -> 0
A31: Abastecimiento y compras | B31: Gestión de datos maestros | C31: MM-03_Datos maestros de compras(MM_M020) | E31: Creación de condiciones. Creación de registros info | F31: Las condiciones son los acuerdos que se tienen con los proveedores sobre precios, recargos, descuentos, etc. Las cuales pueden ser empleados por los documentos logísticos. Los registros info relacionan la información de los materiales con los proveedores como acuerdos comerciales. | G31: Precios: manual o de registro info Descuentos: fijos y porcentual Recargos: fijo y porcentual. Impuestos : IGV Costos Indirectos : Transporte e instalación. Importaciones: comisiones agente de aduana fijo y %, flete, seguro,%advalorem,almacenaje, transporte, estiba, cuadrilla, gasto portuario, vistos buenos, servicios logísticos, gastos administrativos, Instalación. Se utiliza para compras nacionales e importadas. | H31: Se excluye variaciones o lógicas especiales para los esquemas de cálculos o condiciones definidos en el BPD. | I31: MM | J31: YS0_S4HANA_BP_001 YS0_S4HANA_MM_001 | K31: YS0_S4HANA_EO_001 YS0_S4HANA_EO_C001 | M31: 1 | O31: MC_MM_M030_Registro de condiciones MC_MM_M040_Registros info | P31: 04 Terminado | R31: 1 | S31: DM | T31: =+VLOOKUP(S31,Atributos!$P$2:$W$5,3)*R31 -> 1 | U31: =+VLOOKUP(S31,Atributos!$P$2:$W$5,4)*R31 -> 1 | V31: =+VLOOKUP(S31,Atributos!$P$2:$W$5,5)*R31 -> 8 | W31: =+VLOOKUP(S31,Atributos!$P$2:$W$5,6)*R31 -> 8 | X31: =+VLOOKUP(S31,Atributos!$P$2:$W$5,7)*R31 -> 8 | Y31: =+VLOOKUP(S31,Atributos!$P$2:$W$5,8)*R31 -> 0
A32: Abastecimiento y compras | B32: Operaciones de compras | C32: MM-10_Compras de stock(MM_P050) | D32: J45 | E32: Generación de Solicitud de Pedido Liberación de Solicitud de Pedido Generación de Pedido de Compra Liberación de Pedido de Compra Envío de formato de pedido de compra al proveedor. Entrada de Mercadería Registro de Facturas Reportes | F32: Este proceso en SAP permite brindar soporte al Proceso de Abastecimiento de Proveedores Locales o extranjeros para la adquisición de existencias de una empresa. Cabe mencionar que, para los procesos definidos en SAP, las existencias son aquellas que: - Emplean un código de material, que contará con gestión de cantidad y valor. - El ingreso de dicho material es contabilizado en ctas. de existencias. | G32: -Compras asociadas a contratos por valor afectos a IGV -Compras asociadas a contratos por importe inafectos a IGV. -Compras sin estrategias de liberación con retenciones. -Compras con estrategia de liberación con detracciones. -Compras con descuentos, recargos, costos indirectos,afectos y no afectos al IGV. -Compras con posiciones gratuitas -Entregas parciales. -Facturación parcial. -Anulación de entrega. -Anulación de factura. -Compras locales e importaciones. | H32: No se usa planes de entrega. No se utiliza entregas entrantes ni confirmaciones de OC. | I32: MM | J32: YS0_S4HANA_MM_001 | K32: YS0_S4HANA_EO_001 YS0_S4HANA_EO_C001 | L32: Las transacciones de petición de ofertas y ofertas están obsoletas. Hay que volver a configurar el proceso basado en las nuevas prácticas de SAP a través de apps creadas para este fin. | M32: 1 | O32: MC_MM_P051_Pedidos | P32: 04 Terminado | Q32: S0_B001_00_010 | R32: 1 | S32: PR | T32: =+VLOOKUP(S32,Atributos!$P$2:$W$5,3)*R32 -> 1 | U32: =+VLOOKUP(S32,Atributos!$P$2:$W$5,4)*R32 -> 2 | V32: =+VLOOKUP(S32,Atributos!$P$2:$W$5,5)*R32 -> 16 | W32: =+VLOOKUP(S32,Atributos!$P$2:$W$5,6)*R32 -> 32 | X32: =+VLOOKUP(S32,Atributos!$P$2:$W$5,7)*R32 -> 8 | Y32: =+VLOOKUP(S32,Atributos!$P$2:$W$5,8)*R32 -> 8
A33: Abastecimiento y compras | B33: Operaciones de compras | C33: MM-11_Compra de servicios(MM_P051) | D33: 22Z | E33: Generación de Solicitud de Pedido Liberación de Solicitud de Pedido Generación de Pedido de Abierto Liberación de Pedido Abierto Generación de Pedido de Compra Liberación de Pedido de Compra Envío de formato de pedido de compra al proveedor. Entrada de Mercadería Registro de Facturas Reportes | F33: Este proceso de compras utiliza solicitudes de pedido o directamente órdenes de compra. Se realiza el flujo de compras con aprobaciones de órdenes de compra, hoja de entrada de servicio y registro de la factura. A diferencia de las compras de stock, este proceso requiere de una imputación en las solicitudes de pedidos u órdenes de compra ya que los importes son registrados directamente en el gasto ya que no se requiere tenerlos en cuentas de inventario. | G33: -Compras asociadas a contratos por valor afectos a IGV -Compras asociadas a contratos por importe inafectos a IGV. -Compras sin estrategias de liberación con retenciones. -Compras con estrategia de liberación con detracciones. -Compras con descuentos, recargos, costos indirectos,afectos y no afectos al IGV. -Compras con posiciones gratuitas -Entregas parciales. -Facturación parcial. -Anulación de entrega. -Anulación de factura. -Compras locales e importaciones. | H33: No se usa planes de entrega. No se utiliza entregas entrantes ni confirmaciones de OC. | I33: MM | J33: YS0_S4HANA_MM_001 | K33: YS0_S4HANA_EO_001 YS0_S4HANA_EO_C001 | L33: Las transacciones de petición de ofertas y ofertas están obsoletas. Hay que volver a configurar el proceso basado en las nuevas prácticas de SAP a través de apps creadas para este fin. | M33: 1 | O33: MC_MM_P051_Pedidos | P33: 04 Terminado | Q33: S0_B001_00_010 | R33: 1 | S33: PR | T33: =+VLOOKUP(S33,Atributos!$P$2:$W$5,3)*R33 -> 1 | U33: =+VLOOKUP(S33,Atributos!$P$2:$W$5,4)*R33 -> 2 | V33: =+VLOOKUP(S33,Atributos!$P$2:$W$5,5)*R33 -> 16 | W33: =+VLOOKUP(S33,Atributos!$P$2:$W$5,6)*R33 -> 32 | X33: =+VLOOKUP(S33,Atributos!$P$2:$W$5,7)*R33 -> 8 | Y33: =+VLOOKUP(S33,Atributos!$P$2:$W$5,8)*R33 -> 8
A34: Abastecimiento y compras | B34: Operaciones de compras | C34: MM-12_Compras de consumibles(MM_P051) | D34: BNX 18J | E34: Tipos de Imputación - Centro de Costo - Orden CO Compra de Bienes - Generación de Solicitud de Pedido - Liberación de Solicitud de Pedido - Generación de Pedido de Compra - Liberación de Pedido de Compra - Envío de formato de pedido de compra al proveedor. - Entrada de Mercadería - Registro de Facturas Reportes | F34: Este proceso de compras utiliza solicitudes de pedido o directamente órdenes de compra. Se realiza el flujo de compras con aprobaciones de órdenes de compra, ingresos de mercadería al almacén y registro de la factura. A diferencia de las compras de stock, este proceso requiere de una imputación en las solicitudes de pedidos u órdenes de compra ya que los importes son registrados directamente en el gasto ya que no se requiere tenerlos en cuentas de inventario. Este proceso está orientado a compra de materiales que no forman parte del core del negocio pero que son requeridos para la gestión y están dentro del presupuesto anual de la compañía como por ejemplo la compra de útiles de economato, activos fijos, etc. | G34: -Compras de material no valorado imputados a varios centro de costos. -Compras de suministro imputadas a una orden CO. -Compras imputadas a un activo fijo. -Compras de servicios imputada a un centro de costos. -Imputación U.(Desconocida). | I34: MM | J34: YS0_S4HANA_MM_001 | K34: YS0_S4HANA_EO_001 YS0_S4HANA_EO_C001 | L34: Las transacciones de petición de ofertas y ofertas están obsoletas. Hay que volver a configurar el proceso basado en las nuevas prácticas de SAP a través de apps creadas para este fin. SAP indica que debemos usar materiales SERV para servicios, eso implica que va a ser obsoleto el uso de las HES? | M34: 1 | P34: 04 Terminado | R34: 1 | S34: PR | T34: =+VLOOKUP(S34,Atributos!$P$2:$W$5,3)*R34 -> 1 | U34: =+VLOOKUP(S34,Atributos!$P$2:$W$5,4)*R34 -> 2 | V34: =+VLOOKUP(S34,Atributos!$P$2:$W$5,5)*R34 -> 16 | W34: =+VLOOKUP(S34,Atributos!$P$2:$W$5,6)*R34 -> 32 | X34: =+VLOOKUP(S34,Atributos!$P$2:$W$5,7)*R34 -> 8 | Y34: =+VLOOKUP(S34,Atributos!$P$2:$W$5,8)*R34 -> 8
A35: Abastecimiento y compras | B35: Abastecimiento y gestión de contratos | C35: MM-13_Compras con contratos(MM_P052) | D35: BMD | E35: Generación de Solicitud de Pedido Generación de Pedido de Abierto Liberación de Pedido Abierto Generación de Pedido de Compra Entrada de mercancía Registro de Factura del Proveedor Extranjero de la Orden de Compra Registro de Facturas de Costos Indirectos Reportes | F35: Este proceso de compras se utiliza para tener mayor predictibilidad en el abastecimiento ya que previamente se puede negociar con los proveedores volúmenes importantes de compras a lo largo de un periodo determinado logrando mejores condiciones de cumplimiento por parte del proveedor. El proceso inicia con una solicitud de pedido que contienen el volumen total del requerimiento, en base a este volumen se negocia un contrato con el proveedor. El gerente de compra aprueba la formulación del contrato. Luego todas las solicitudes de compra pueden usar las condiciones comerciales negociadas en los contratos generados hasta agotar el volumen negociado con el proveedor. Los contratos también se pueden usar para procesos de abastecimiento que involucran importación. | G35: Compra con pedido abierto asociado a solped con condiciones de importación: - Comisiones agente de aduana fijo y %. - Flete. - Seguro. - %advalorem. - Almacenaje, transporte, estiba, cuadrilla, gasto portuario, vistos buenos, servicios logísticos, gastos administrativos, Instalación. | H35: Sin gestión de stock en operadores logísticos | I35: MM | J35: YS0_S4HANA_MM_001 | K35: YS0_S4HANA_EO_001 YS0_S4HANA_EO_C001 | L35: Las transacciones de petición de ofertas y ofertas están obsoletas. Hay que volver a configurar el proceso basado en las nuevas prácticas de SAP a través de apps creadas para este fin. | M35: 1 | P35: 04 Terminado | R35: 1 | S35: PR | T35: =+VLOOKUP(S35,Atributos!$P$2:$W$5,3)*R35 -> 1 | U35: =+VLOOKUP(S35,Atributos!$P$2:$W$5,4)*R35 -> 2 | V35: =+VLOOKUP(S35,Atributos!$P$2:$W$5,5)*R35 -> 16 | W35: =+VLOOKUP(S35,Atributos!$P$2:$W$5,6)*R35 -> 32 | X35: =+VLOOKUP(S35,Atributos!$P$2:$W$5,7)*R35 -> 8 | Y35: =+VLOOKUP(S35,Atributos!$P$2:$W$5,8)*R35 -> 8
A36: Abastecimiento y compras | B36: Operaciones de compras | C36: MM-14_Consignaciones(MM_P053) | D36: 2LG | E36: Generación de Solicitud de Pedido de Consignación Generación o actualización de registro Info por consignación Generación de Pedido de Compra por consignación Liberación de Pedido de compra de consignación Generación de Formulario de Orden de Compra al proveedor Entrada de Mercadería a consignación Traspaso de Consignación a libre utilización (stock propio) Toma de Materiales en Consignación Liquidación de materiales en consignación tomados Reportes | F36: Este proceso conserva las consideraciones del Proceso de Compra Nacional mencionada anteriormente y se le suman las siguientes particularidades: 1. El proveedor suministra los materiales (artículos en consignación) y la empresa que realiza la adquisición, los guarda en sus almacenes o bodegas. Sin embargo, el proveedor queda como el propietario legal del material hasta que sean tomado. 2. Para el pago de la factura, se realizan cortes periódicos coordinados entre el proveedor y la empresa que realiza la adquisición o compra, para identificar cual ha sido el consumo a la fecha y realizar el pago, en función de un precio, previamente acordado antes de realizar el consumo. 3. SAP permite a través de sus reportes, identificar el material que se encuentra en estado consignado y controlar, una vez pase al stock propio. Obs. Este modelo, legalmente conlleva a presentar al estado un libro de consignación. Generalmente utilizado en empresas que consumen combustibles a gran escala. | G36: - Proceso de consignación de proveedor simple: Generación de solicitud de compra, generación de pedido de compra, entrada de mercadería a consignación, toma de materiales y liquidación. | I36: MM | J36: YS0_S4HANA_MM_001 | K36: YS0_S4HANA_EO_001 YS0_S4HANA_EO_C001 | M36: 1 | P36: 04 Terminado | R36: 1 | S36: PR | T36: =+VLOOKUP(S36,Atributos!$P$2:$W$5,3)*R36 -> 1 | U36: =+VLOOKUP(S36,Atributos!$P$2:$W$5,4)*R36 -> 2 | V36: =+VLOOKUP(S36,Atributos!$P$2:$W$5,5)*R36 -> 16 | W36: =+VLOOKUP(S36,Atributos!$P$2:$W$5,6)*R36 -> 32 | X36: =+VLOOKUP(S36,Atributos!$P$2:$W$5,7)*R36 -> 8 | Y36: =+VLOOKUP(S36,Atributos!$P$2:$W$5,8)*R36 -> 8
A37: Abastecimiento y compras | B37: Operaciones de compras | C37: MM-15_Subcontratación(MM_P054) | D37: BMY | E37: Generación de la Solicitud de Pedido Liberación de la Solicitud de Pedido Generación o actualización de registro Info por subcontratación Generación de Pedido de Subcontratación Liberación del Pedido de subcontratación Generación de Formulario de Compra al proveedor Entrega de componentes a Proveedor por Subcontratación (Emisión de guía de remisión) Entrada de Mercadería del producto final Registro de Factura Reportes | F37: Este proceso conserva las consideraciones del Proceso de Compra Nacional mencionada anteriormente y se le suman las siguientes particularidades: 1. Durante el proceso de compra, el proveedor puede recibir todos o una parte de los componentes, con los que fabricará o ensamblará para poder abastecer con un producto final. 2. SAP permite optimizar el proceso, armando listas de materiales para que se dé una propuesta automática a los materiales que debemos entregar al proveedor. Si bien el proceso soporta el uso de lista de materiales, debe considerarse el esfuerzo necesario por parte del negocio de crear este dato maestros y darle el mantenimiento adecuado. 3. SAP cuenta con reportes que permitirán monitorear el material que está siendo entregado al proveedor; así como, controlar el stock del nuevo material una vez se dé el ingreso. | G37: - Proceso de subcontratación simple: Los materiales entregados al proveedor salen del mismo centro donde el proveedor entrega el producto procesado. | H37: Se excluye | I37: MM | J37: YS0_S4HANA_MM_001 | K37: YS0_S4HANA_EO_001 YS0_S4HANA_EO_C001 | M37: 1 | P37: 04 Terminado | R37: 1 | S37: PR | T37: =+VLOOKUP(S37,Atributos!$P$2:$W$5,3)*R37 -> 1 | U37: =+VLOOKUP(S37,Atributos!$P$2:$W$5,4)*R37 -> 2 | V37: =+VLOOKUP(S37,Atributos!$P$2:$W$5,5)*R37 -> 16 | W37: =+VLOOKUP(S37,Atributos!$P$2:$W$5,6)*R37 -> 32 | X37: =+VLOOKUP(S37,Atributos!$P$2:$W$5,7)*R37 -> 8 | Y37: =+VLOOKUP(S37,Atributos!$P$2:$W$5,8)*R37 -> 8
